2024-11-14 00:32:26,002 INFO    MainThread:35933 [wandb_setup.py:_flush():79] Current SDK version is 0.18.3
2024-11-14 00:32:26,002 INFO    MainThread:35933 [wandb_setup.py:_flush():79] Configure stats pid to 35933
2024-11-14 00:32:26,003 INFO    MainThread:35933 [wandb_setup.py:_flush():79] Loading settings from /Users/dan/.config/wandb/settings
2024-11-14 00:32:26,003 INFO    MainThread:35933 [wandb_setup.py:_flush():79] Loading settings from /Users/dan/Documents/src/COMP-STUDY/synced/wandb/settings
2024-11-14 00:32:26,003 INFO    MainThread:35933 [wandb_setup.py:_flush():79] Loading settings from environment variables: {'_require_legacy_service': 'true', 'entity': 'ctufit', 'project': 'pelanekd-ALcompstudy-test', 'sweep_id': 'dxq2cb8g', 'root_dir': '/Users/dan/Documents/src/COMP-STUDY/synced', 'run_id': 'om3gjoyw', 'sweep_param_path': '/Users/dan/Documents/src/COMP-STUDY/synced/wandb/sweep-dxq2cb8g/config-om3gjoyw.yaml'}
2024-11-14 00:32:26,003 INFO    MainThread:35933 [wandb_setup.py:_flush():79] Applying setup settings: {'mode': None, '_disable_service': None}
2024-11-14 00:32:26,003 INFO    MainThread:35933 [wandb_setup.py:_flush():79] Inferring run settings from compute environment: {'program_relpath': 'uncertainty_strategy.py', 'program_abspath': '/Users/dan/Documents/src/COMP-STUDY/synced/uncertainty_strategy.py', 'program': '/Users/dan/Documents/src/COMP-STUDY/synced/uncertainty_strategy.py'}
2024-11-14 00:32:26,003 INFO    MainThread:35933 [wandb_setup.py:_flush():79] Applying login settings: {}
2024-11-14 00:32:26,003 INFO    MainThread:35933 [wandb_init.py:_log_setup():532] Logging user logs to /Users/dan/Documents/src/COMP-STUDY/synced/wandb/run-20241114_003225-om3gjoyw/logs/debug.log
2024-11-14 00:32:26,003 INFO    MainThread:35933 [wandb_init.py:_log_setup():533] Logging internal logs to /Users/dan/Documents/src/COMP-STUDY/synced/wandb/run-20241114_003225-om3gjoyw/logs/debug-internal.log
2024-11-14 00:32:26,003 INFO    MainThread:35933 [wandb_init.py:init():617] calling init triggers
2024-11-14 00:32:26,003 INFO    MainThread:35933 [wandb_init.py:init():624] wandb.init called with sweep_config: {'average_unc_cutoff': 0.022356404636860058, 'bagging_fraction': 0.8116110450471201, 'feature_fraction': 0.472433007886386, 'learning_rate': 0.011441173343604252, 'min_child_samples': 44, 'min_data_in_leaf': 1244, 'num_leaves': 225}
config: {}
2024-11-14 00:32:26,003 INFO    MainThread:35933 [wandb_init.py:init():667] starting backend
2024-11-14 00:32:26,003 INFO    MainThread:35933 [wandb_init.py:init():671] sending inform_init request
2024-11-14 00:32:26,009 INFO    MainThread:35933 [backend.py:_multiprocessing_setup():104] multiprocessing start_methods=spawn,fork,forkserver, using: spawn
2024-11-14 00:32:26,009 INFO    MainThread:35933 [wandb_init.py:init():684] backend started and connected
2024-11-14 00:32:26,018 INFO    MainThread:35933 [wandb_run.py:_config_callback():1394] config_cb None None {'average_unc_cutoff': 0.022356404636860058, 'bagging_fraction': 0.8116110450471201, 'feature_fraction': 0.472433007886386, 'learning_rate': 0.011441173343604252, 'min_child_samples': 44, 'min_data_in_leaf': 1244, 'num_leaves': 225}
2024-11-14 00:32:26,021 INFO    MainThread:35933 [wandb_init.py:init():779] updated telemetry
2024-11-14 00:32:26,035 INFO    MainThread:35933 [wandb_init.py:init():812] communicating run to backend with 90.0 second timeout
2024-11-14 00:32:26,430 INFO    MainThread:35933 [wandb_init.py:init():863] starting run threads in backend
2024-11-14 00:32:56,726 INFO    MainThread:35933 [wandb_run.py:_console_start():2465] atexit reg
2024-11-14 00:32:56,726 INFO    MainThread:35933 [wandb_run.py:_redirect():2313] redirect: wrap_raw
2024-11-14 00:32:56,727 INFO    MainThread:35933 [wandb_run.py:_redirect():2378] Wrapping output streams.
2024-11-14 00:32:56,727 INFO    MainThread:35933 [wandb_run.py:_redirect():2403] Redirects installed.
2024-11-14 00:32:56,728 INFO    MainThread:35933 [wandb_init.py:init():907] run started, returning control to user process
2024-11-14 00:42:00,304 INFO    MainThread:35933 [retry.py:__call__():172] Retry attempt failed:
Traceback (most recent call last):
  File "/Library/Frameworks/Python.framework/Versions/3.11/lib/python3.11/site-packages/urllib3/connection.py", line 198, in _new_conn
    sock = connection.create_connection(
           ^^^^^^^^^^^^^^^^^^^^^^^^^^^^^
  File "/Library/Frameworks/Python.framework/Versions/3.11/lib/python3.11/site-packages/urllib3/util/connection.py", line 60, in create_connection
    for res in socket.getaddrinfo(host, port, family, socket.SOCK_STREAM):
               ^^^^^^^^^^^^^^^^^^^^^^^^^^^^^^^^^^^^^^^^^^^^^^^^^^^^^^^^^^
  File "/Library/Frameworks/Python.framework/Versions/3.11/lib/python3.11/socket.py", line 962, in getaddrinfo
    for res in _socket.getaddrinfo(host, port, family, type, proto, flags):
               ^^^^^^^^^^^^^^^^^^^^^^^^^^^^^^^^^^^^^^^^^^^^^^^^^^^^^^^^^^^
socket.gaierror: [Errno 8] nodename nor servname provided, or not known

The above exception was the direct cause of the following exception:

Traceback (most recent call last):
  File "/Library/Frameworks/Python.framework/Versions/3.11/lib/python3.11/site-packages/urllib3/connectionpool.py", line 793, in urlopen
    response = self._make_request(
               ^^^^^^^^^^^^^^^^^^^
  File "/Library/Frameworks/Python.framework/Versions/3.11/lib/python3.11/site-packages/urllib3/connectionpool.py", line 491, in _make_request
    raise new_e
  File "/Library/Frameworks/Python.framework/Versions/3.11/lib/python3.11/site-packages/urllib3/connectionpool.py", line 467, in _make_request
    self._validate_conn(conn)
  File "/Library/Frameworks/Python.framework/Versions/3.11/lib/python3.11/site-packages/urllib3/connectionpool.py", line 1099, in _validate_conn
    conn.connect()
  File "/Library/Frameworks/Python.framework/Versions/3.11/lib/python3.11/site-packages/urllib3/connection.py", line 616, in connect
    self.sock = sock = self._new_conn()
                       ^^^^^^^^^^^^^^^^
  File "/Library/Frameworks/Python.framework/Versions/3.11/lib/python3.11/site-packages/urllib3/connection.py", line 205, in _new_conn
    raise NameResolutionError(self.host, self, e) from e
urllib3.exceptions.NameResolutionError: <urllib3.connection.HTTPSConnection object at 0x28d99a590>: Failed to resolve 'api.wandb.ai' ([Errno 8] nodename nor servname provided, or not known)

The above exception was the direct cause of the following exception:

Traceback (most recent call last):
  File "/Library/Frameworks/Python.framework/Versions/3.11/lib/python3.11/site-packages/requests/adapters.py", line 589, in send
    resp = conn.urlopen(
           ^^^^^^^^^^^^^
  File "/Library/Frameworks/Python.framework/Versions/3.11/lib/python3.11/site-packages/urllib3/connectionpool.py", line 847, in urlopen
    retries = retries.increment(
              ^^^^^^^^^^^^^^^^^^
  File "/Library/Frameworks/Python.framework/Versions/3.11/lib/python3.11/site-packages/urllib3/util/retry.py", line 515, in increment
    raise MaxRetryError(_pool, url, reason) from reason  # type: ignore[arg-type]
    ^^^^^^^^^^^^^^^^^^^^^^^^^^^^^^^^^^^^^^^^^^^^^^^^^^^
urllib3.exceptions.MaxRetryError: HTTPSConnectionPool(host='api.wandb.ai', port=443): Max retries exceeded with url: /graphql (Caused by NameResolutionError("<urllib3.connection.HTTPSConnection object at 0x28d99a590>: Failed to resolve 'api.wandb.ai' ([Errno 8] nodename nor servname provided, or not known)"))

During handling of the above exception, another exception occurred:

Traceback (most recent call last):
  File "/Library/Frameworks/Python.framework/Versions/3.11/lib/python3.11/site-packages/wandb/sdk/lib/retry.py", line 131, in __call__
    result = self._call_fn(*args, **kwargs)
             ^^^^^^^^^^^^^^^^^^^^^^^^^^^^^^
  File "/Library/Frameworks/Python.framework/Versions/3.11/lib/python3.11/site-packages/wandb/apis/public/api.py", line 70, in execute
    return self._client.execute(*args, **kwargs)
           ^^^^^^^^^^^^^^^^^^^^^^^^^^^^^^^^^^^^^
  File "/Library/Frameworks/Python.framework/Versions/3.11/lib/python3.11/site-packages/wandb/vendor/gql-0.2.0/wandb_gql/client.py", line 52, in execute
    result = self._get_result(document, *args, **kwargs)
             ^^^^^^^^^^^^^^^^^^^^^^^^^^^^^^^^^^^^^^^^^^^
  File "/Library/Frameworks/Python.framework/Versions/3.11/lib/python3.11/site-packages/wandb/vendor/gql-0.2.0/wandb_gql/client.py", line 60, in _get_result
    return self.transport.execute(document, *args, **kwargs)
           ^^^^^^^^^^^^^^^^^^^^^^^^^^^^^^^^^^^^^^^^^^^^^^^^^
  File "/Library/Frameworks/Python.framework/Versions/3.11/lib/python3.11/site-packages/wandb/sdk/lib/gql_request.py", line 58, in execute
    request = self.session.post(self.url, **post_args)
              ^^^^^^^^^^^^^^^^^^^^^^^^^^^^^^^^^^^^^^^^
  File "/Library/Frameworks/Python.framework/Versions/3.11/lib/python3.11/site-packages/requests/sessions.py", line 637, in post
    return self.request("POST", url, data=data, json=json, **kwargs)
           ^^^^^^^^^^^^^^^^^^^^^^^^^^^^^^^^^^^^^^^^^^^^^^^^^^^^^^^^^
  File "/Library/Frameworks/Python.framework/Versions/3.11/lib/python3.11/site-packages/requests/sessions.py", line 589, in request
    resp = self.send(prep, **send_kwargs)
           ^^^^^^^^^^^^^^^^^^^^^^^^^^^^^^
  File "/Library/Frameworks/Python.framework/Versions/3.11/lib/python3.11/site-packages/requests/sessions.py", line 703, in send
    r = adapter.send(request, **kwargs)
        ^^^^^^^^^^^^^^^^^^^^^^^^^^^^^^^
  File "/Library/Frameworks/Python.framework/Versions/3.11/lib/python3.11/site-packages/requests/adapters.py", line 622, in send
    raise ConnectionError(e, request=request)
requests.exceptions.ConnectionError: HTTPSConnectionPool(host='api.wandb.ai', port=443): Max retries exceeded with url: /graphql (Caused by NameResolutionError("<urllib3.connection.HTTPSConnection object at 0x28d99a590>: Failed to resolve 'api.wandb.ai' ([Errno 8] nodename nor servname provided, or not known)"))
2024-11-14 00:42:36,546 INFO    MainThread:35933 [retry.py:__call__():172] Retry attempt failed:
Traceback (most recent call last):
  File "/Library/Frameworks/Python.framework/Versions/3.11/lib/python3.11/site-packages/urllib3/connection.py", line 198, in _new_conn
    sock = connection.create_connection(
           ^^^^^^^^^^^^^^^^^^^^^^^^^^^^^
  File "/Library/Frameworks/Python.framework/Versions/3.11/lib/python3.11/site-packages/urllib3/util/connection.py", line 60, in create_connection
    for res in socket.getaddrinfo(host, port, family, socket.SOCK_STREAM):
               ^^^^^^^^^^^^^^^^^^^^^^^^^^^^^^^^^^^^^^^^^^^^^^^^^^^^^^^^^^
  File "/Library/Frameworks/Python.framework/Versions/3.11/lib/python3.11/socket.py", line 962, in getaddrinfo
    for res in _socket.getaddrinfo(host, port, family, type, proto, flags):
               ^^^^^^^^^^^^^^^^^^^^^^^^^^^^^^^^^^^^^^^^^^^^^^^^^^^^^^^^^^^
socket.gaierror: [Errno 8] nodename nor servname provided, or not known

The above exception was the direct cause of the following exception:

Traceback (most recent call last):
  File "/Library/Frameworks/Python.framework/Versions/3.11/lib/python3.11/site-packages/urllib3/connectionpool.py", line 793, in urlopen
    response = self._make_request(
               ^^^^^^^^^^^^^^^^^^^
  File "/Library/Frameworks/Python.framework/Versions/3.11/lib/python3.11/site-packages/urllib3/connectionpool.py", line 491, in _make_request
    raise new_e
  File "/Library/Frameworks/Python.framework/Versions/3.11/lib/python3.11/site-packages/urllib3/connectionpool.py", line 467, in _make_request
    self._validate_conn(conn)
  File "/Library/Frameworks/Python.framework/Versions/3.11/lib/python3.11/site-packages/urllib3/connectionpool.py", line 1099, in _validate_conn
    conn.connect()
  File "/Library/Frameworks/Python.framework/Versions/3.11/lib/python3.11/site-packages/urllib3/connection.py", line 616, in connect
    self.sock = sock = self._new_conn()
                       ^^^^^^^^^^^^^^^^
  File "/Library/Frameworks/Python.framework/Versions/3.11/lib/python3.11/site-packages/urllib3/connection.py", line 205, in _new_conn
    raise NameResolutionError(self.host, self, e) from e
urllib3.exceptions.NameResolutionError: <urllib3.connection.HTTPSConnection object at 0x28eaecb90>: Failed to resolve 'api.wandb.ai' ([Errno 8] nodename nor servname provided, or not known)

The above exception was the direct cause of the following exception:

Traceback (most recent call last):
  File "/Library/Frameworks/Python.framework/Versions/3.11/lib/python3.11/site-packages/requests/adapters.py", line 589, in send
    resp = conn.urlopen(
           ^^^^^^^^^^^^^
  File "/Library/Frameworks/Python.framework/Versions/3.11/lib/python3.11/site-packages/urllib3/connectionpool.py", line 847, in urlopen
    retries = retries.increment(
              ^^^^^^^^^^^^^^^^^^
  File "/Library/Frameworks/Python.framework/Versions/3.11/lib/python3.11/site-packages/urllib3/util/retry.py", line 515, in increment
    raise MaxRetryError(_pool, url, reason) from reason  # type: ignore[arg-type]
    ^^^^^^^^^^^^^^^^^^^^^^^^^^^^^^^^^^^^^^^^^^^^^^^^^^^
urllib3.exceptions.MaxRetryError: HTTPSConnectionPool(host='api.wandb.ai', port=443): Max retries exceeded with url: /graphql (Caused by NameResolutionError("<urllib3.connection.HTTPSConnection object at 0x28eaecb90>: Failed to resolve 'api.wandb.ai' ([Errno 8] nodename nor servname provided, or not known)"))

During handling of the above exception, another exception occurred:

Traceback (most recent call last):
  File "/Library/Frameworks/Python.framework/Versions/3.11/lib/python3.11/site-packages/wandb/sdk/lib/retry.py", line 131, in __call__
    result = self._call_fn(*args, **kwargs)
             ^^^^^^^^^^^^^^^^^^^^^^^^^^^^^^
  File "/Library/Frameworks/Python.framework/Versions/3.11/lib/python3.11/site-packages/wandb/sdk/internal/internal_api.py", line 347, in execute
    return self.client.execute(*args, **kwargs)  # type: ignore
           ^^^^^^^^^^^^^^^^^^^^^^^^^^^^^^^^^^^^
  File "/Library/Frameworks/Python.framework/Versions/3.11/lib/python3.11/site-packages/wandb/vendor/gql-0.2.0/wandb_gql/client.py", line 52, in execute
    result = self._get_result(document, *args, **kwargs)
             ^^^^^^^^^^^^^^^^^^^^^^^^^^^^^^^^^^^^^^^^^^^
  File "/Library/Frameworks/Python.framework/Versions/3.11/lib/python3.11/site-packages/wandb/vendor/gql-0.2.0/wandb_gql/client.py", line 60, in _get_result
    return self.transport.execute(document, *args, **kwargs)
           ^^^^^^^^^^^^^^^^^^^^^^^^^^^^^^^^^^^^^^^^^^^^^^^^^
  File "/Library/Frameworks/Python.framework/Versions/3.11/lib/python3.11/site-packages/wandb/sdk/lib/gql_request.py", line 58, in execute
    request = self.session.post(self.url, **post_args)
              ^^^^^^^^^^^^^^^^^^^^^^^^^^^^^^^^^^^^^^^^
  File "/Library/Frameworks/Python.framework/Versions/3.11/lib/python3.11/site-packages/requests/sessions.py", line 637, in post
    return self.request("POST", url, data=data, json=json, **kwargs)
           ^^^^^^^^^^^^^^^^^^^^^^^^^^^^^^^^^^^^^^^^^^^^^^^^^^^^^^^^^
  File "/Library/Frameworks/Python.framework/Versions/3.11/lib/python3.11/site-packages/requests/sessions.py", line 589, in request
    resp = self.send(prep, **send_kwargs)
           ^^^^^^^^^^^^^^^^^^^^^^^^^^^^^^
  File "/Library/Frameworks/Python.framework/Versions/3.11/lib/python3.11/site-packages/requests/sessions.py", line 703, in send
    r = adapter.send(request, **kwargs)
        ^^^^^^^^^^^^^^^^^^^^^^^^^^^^^^^
  File "/Library/Frameworks/Python.framework/Versions/3.11/lib/python3.11/site-packages/requests/adapters.py", line 622, in send
    raise ConnectionError(e, request=request)
requests.exceptions.ConnectionError: HTTPSConnectionPool(host='api.wandb.ai', port=443): Max retries exceeded with url: /graphql (Caused by NameResolutionError("<urllib3.connection.HTTPSConnection object at 0x28eaecb90>: Failed to resolve 'api.wandb.ai' ([Errno 8] nodename nor servname provided, or not known)"))
